<?xml version="1.0"?>

<robot xmlns:xacro="http://www.ros.org/wiki/xacro" name="sumo">
  <xacro:macro name="front_camera" params="name">
    <!-- Camera -->
    <link name="camera_link">
      <visual>
        <geometry>
          <mesh filename="package://computer_vision_pkg/meshes/head.dae" scale=".5 .5 .5"/>
        </geometry>
      </visual>
      <collision>
        <geometry>
          <sphere radius="0.02"/>
        </geometry>
      </collision>
      <inertial>
        <mass value="0.10"/>
        <inertia ixx="0.03" ixy="0.0" ixz="0.0" iyy="0.03" iyz="0.0" izz="0.03"/>
      </inertial>
    </link>
    
    <joint name="base_to_camera" type="continuous">
      <axis xyz="0 0 1"/>
      <parent link="base_link"/>
      <child link="camera_link"/>
      <origin rpy="0 0 0" xyz="0.05 0 0.02"/>
      <limit effort="30" velocity="1.0"/>
    </joint>
    
    <transmission name="camera_transmission">
      <type>transmission_interface/SimpleTransmission</type>
      <actuator name="$camera_motor">
        <mechanicalReduction>1</mechanicalReduction>
      </actuator>
      <joint name="base_to_camera">
        <hardwareInterface>hardware_interface/PositionJointInterface</hardwareInterface>
      </joint>
    </transmission>
    
    <gazebo reference="camera_link">
    <sensor type="camera" name="camera1">
      <update_rate>30.0</update_rate>
      <camera name="camera">
        <horizontal_fov>1.3962634</horizontal_fov>
        <image>
          <width>800</width>
          <height>800</height>
          <format>R8G8B8</format>
        </image>
        <clip>
          <near>0.02</near>
          <far>300</far>
        </clip>
        <noise>
          <type>gaussian</type>
          <!-- Noise is sampled independently per pixel on each frame.
               That pixel's noise value is added to each of its color
               channels, which at that point lie in the range [0,1]. -->
          <mean>0.0</mean>
          <stddev>0.007</stddev>
        </noise>
      </camera>
      <plugin name="camera_controller" filename="libgazebo_ros_camera.so">
        <alwaysOn>true</alwaysOn>
        <updateRate>0.0</updateRate>
        <cameraName>camera</cameraName>
        <imageTopicName>image_raw</imageTopicName>
        <cameraInfoTopicName>camera_info</cameraInfoTopicName>
        <frameName>camera_link</frameName>
        <hackBaseline>0.07</hackBaseline>
        <distortionK1>0.0</distortionK1>
        <distortionK2>0.0</distortionK2>
        <distortionK3>0.0</distortionK3>
        <distortionT1>0.0</distortionT1>
        <distortionT2>0.0</distortionT2>
      </plugin>
    </sensor>
  </gazebo>
  </xacro:macro>
</robot>
