<?xml version="1.0"?>
<robot xmlns:xacro="http://www.ros.org/wiki/xacro" name="my_robot">
<xacro:macro name="head">


    <link name="head_link">
        <visual>
            <origin rpy="0 0 0" xyz="0 0 0"/>
            <geometry>
                <mesh filename="package://tutorial/urdf/head.dae" scale="5 5 5"/>
            </geometry>
        </visual>
        <collision>
            <origin rpy="0 0 0" xyz="0 0 0"/>
            <geometry>
                <sphere radius=".2"/>
            </geometry>
        </collision>
        <inertial>
            <origin rpy="0 0 0" xyz="0 0 0"/>
            <mass value="1"/>
            <inertia ixx="0.03" ixy="0.0" ixz="0.0" iyy="0.03" iyz="0.0" izz="0.03"/>
        </inertial>
    </link>


    <joint name="base_to_head" type="continuous">
        <axis xyz="0 0 1"/>  <!-- changes axis of rotation -->
        <parent link="base_link"/>
        <child link="head_link"/>
        <origin rpy="0 0 0" xyz="0 0 .5"/> <!-- moves the child_frame with respect to parent_frame -->
        <limit effort="30" velocity="1.0"/>
    </joint>


    <transmission name="head_transmission">
        <type>transmission_interface/SimpleTransmission</type>
        <actuator name="$head_motor">
            <mechanicalReduction>1</mechanicalReduction>
        </actuator>
        <joint name="base_to_head">
            <hardwareInterface>hardware_interface/PositionJointInterface</hardwareInterface>
        </joint>
    </transmission>


</xacro:macro>
</robot>

