<?xml version="1.0"?>
<robot name="sumo">
  <link name="dummy">
  </link>
  
  <link name="base_link">
    <visual>
      <geometry>
        <box size="1.5 1 .5"/>
      </geometry>
    </visual>
    <collision>
      <geometry>
        <box size="1.5 1 .5"/>
      </geometry>
    </collision>
    <inertial>
      <mass value="10"/>
      <inertia ixx="2.08" ixy="0.0" ixz="0.0" iyy="2.71" iyz="0.0" izz="1.04"/>
    </inertial>
  </link>
  
  <link name="left_wheel">
    <visual>
      <geometry>
        <cylinder length="0.1" radius="0.5"/>
      </geometry>
    </visual>
    <collision>
      <geometry>
        <cylinder length="0.1" radius="0.5"/>
      </geometry>
    </collision>
    <inertial>
      <mass value="1"/>
      <inertia ixx="0.06" ixy="0.0" ixz="0.0" iyy="0.06" iyz="0.0" izz="0.25"/>
    </inertial>
  </link>
  
  <link name="right_wheel">
    <visual>
      <geometry>
        <cylinder length="0.1" radius="0.5"/>
      </geometry>
    </visual>
    <collision>
      <geometry>
        <cylinder length="0.1" radius="0.5"/>
      </geometry>
    </collision>
    <inertial>
      <mass value="1"/>
      <inertia ixx="0.06" ixy="0.0" ixz="0.0" iyy="0.06" iyz="0.0" izz="0.13"/>
    </inertial>
  </link>
  
  <link name="back_wheel">
    <visual>
      <geometry>
        <sphere radius="0.2"/>
      </geometry>
    </visual>
    <collision>
      <geometry>
        <sphere radius="0.2"/>
      </geometry>
    </collision>
    <inertial>
      <mass value="1"/>
      <inertia ixx="0.03" ixy="0.0" ixz="0.0" iyy="0.03" iyz="0.0" izz="0.03"/>
    </inertial>
  </link>

  <link name="head">
    <visual>
      <geometry>
        <mesh filename="package://sumo/meshes/head.dae" scale="5 5 5"/>
      </geometry>
    </visual>
  </link>
    
  
  <joint name="dummy_joint" type="fixed">
    <parent link="dummy"/>
    <child link="base_link"/>
  </joint>
  
  <joint name="base_to_left_wheel" type="continuous">
    <axis xyz="0 0 1"/>
    <parent link="base_link"/>
    <child link="left_wheel"/>
    <origin rpy="1.57075 0 0" xyz=".5 0.6 0"/>
  </joint>
  
  <joint name="base_to_right_wheel" type="continuous">
    <axis xyz="0 0 1"/>
    <parent link="base_link"/>
    <child link="right_wheel"/>
    <origin rpy="1.57075 0 0" xyz=".5 -0.6 0"/>
  </joint>
  
  <joint name="base_to_back_wheel" type="fixed">
    <parent link="base_link"/>
    <child link="back_wheel"/>
    <origin rpy="0 0 0" xyz="-0.6 0 -0.3"/>
  </joint>
  
  <joint name="base_to_head" type="fixed">
    <parent link="base_link"/>
    <child link="head"/>
    <origin rpy="0 0 0" xyz="0.5 0 0.25"/>
  </joint>
  
</robot>
